<?xml version="1.0" ?>
<robot name="rcj2025" xmlns:xacro="http://www.ros.org/wiki/xacro">

<xacro:include filename="$(find rcj2025_description)/urdf/materials.xacro" />
<xacro:include filename="$(find rcj2025_description)/urdf/rcj2025.trans" />
<xacro:include filename="$(find rcj2025_description)/urdf/rcj2025.gazebo" />

<link name="base_link">
  <inertial>
    <origin xyz="-0.0008436056640299374 0.07287967201339762 -0.002172365932740341" rpy="0 0 0"/>
    <mass value="6.211712403129365"/>
    <inertia ixx="0.020157" iyy="0.025166" izz="0.014889" ixy="0.00016" iyz="-0.000113" ixz="5.6e-05"/>
  </inertial>
  <visual>
    <origin xyz="0 0 0" rpy="0 0 0"/>
    <geometry>
      <mesh filename="file://$(find rcj2025_description)/meshes/base_link.stl" scale="0.001 0.001 0.001"/>
    </geometry>
    <material name="silver"/>
  </visual>
  <collision>
    <origin xyz="0 0 0" rpy="0 0 0"/>
    <geometry>
      <mesh filename="file://$(find rcj2025_description)/meshes/base_link.stl" scale="0.001 0.001 0.001"/>
    </geometry>
  </collision>
</link>

<link name="wheel_left_forward_link_1">
  <inertial>
    <origin xyz="0.0038321243790345877 -8.294581043746807e-07 0.0003539119469892979" rpy="0 0 0"/>
    <mass value="0.30797982883853386"/>
    <inertia ixx="0.000267" iyy="0.000139" izz="0.000139" ixy="0.0" iyz="0.0" ixz="0.0"/>
  </inertial>
  <visual>
    <origin xyz="-0.074905 -0.032003 -0.044995" rpy="0 0 0"/>
    <geometry>
      <mesh filename="file://$(find rcj2025_description)/meshes/wheel_left_forward_link_1.stl" scale="0.001 0.001 0.001"/>
    </geometry>
    <material name="silver"/>
  </visual>
  <collision>
    <origin xyz="-0.074905 -0.032003 -0.044995" rpy="0 0 0"/>
    <geometry>
      <mesh filename="file://$(find rcj2025_description)/meshes/wheel_left_forward_link_1.stl" scale="0.001 0.001 0.001"/>
    </geometry>
  </collision>
</link>

<link name="wheel_right_forward_link_1">
  <inertial>
    <origin xyz="-0.0038321243830769514 -3.458642732385997e-06 0.0003437339119924457" rpy="0 0 0"/>
    <mass value="0.30797982860031553"/>
    <inertia ixx="0.000267" iyy="0.000139" izz="0.000139" ixy="-0.0" iyz="-0.0" ixz="-0.0"/>
  </inertial>
  <visual>
    <origin xyz="0.074905 -0.032003 -0.044995" rpy="0 0 0"/>
    <geometry>
      <mesh filename="file://$(find rcj2025_description)/meshes/wheel_right_forward_link_1.stl" scale="0.001 0.001 0.001"/>
    </geometry>
    <material name="silver"/>
  </visual>
  <collision>
    <origin xyz="0.074905 -0.032003 -0.044995" rpy="0 0 0"/>
    <geometry>
      <mesh filename="file://$(find rcj2025_description)/meshes/wheel_right_forward_link_1.stl" scale="0.001 0.001 0.001"/>
    </geometry>
  </collision>
</link>

<link name="wheel_right_backward_link_1">
  <inertial>
    <origin xyz="-0.0038321243783342313 6.041397013302474e-06 -0.00012307261745363868" rpy="0 0 0"/>
    <mass value="0.3079798288624377"/>
    <inertia ixx="0.000267" iyy="0.000139" izz="0.000139" ixy="-0.0" iyz="-0.0" ixz="0.0"/>
  </inertial>
  <visual>
    <origin xyz="0.074905 -0.032003 0.044995" rpy="0 0 0"/>
    <geometry>
      <mesh filename="file://$(find rcj2025_description)/meshes/wheel_right_backward_link_1.stl" scale="0.001 0.001 0.001"/>
    </geometry>
    <material name="silver"/>
  </visual>
  <collision>
    <origin xyz="0.074905 -0.032003 0.044995" rpy="0 0 0"/>
    <geometry>
      <mesh filename="file://$(find rcj2025_description)/meshes/wheel_right_backward_link_1.stl" scale="0.001 0.001 0.001"/>
    </geometry>
  </collision>
</link>

<link name="wheel_left_backward_link_1">
  <inertial>
    <origin xyz="0.003832124382646254 -3.945927425814955e-06 -0.0003437082381777881" rpy="0 0 0"/>
    <mass value="0.30797982861500756"/>
    <inertia ixx="0.000267" iyy="0.000139" izz="0.000139" ixy="0.0" iyz="0.0" ixz="-0.0"/>
  </inertial>
  <visual>
    <origin xyz="-0.074905 -0.032003 0.044995" rpy="0 0 0"/>
    <geometry>
      <mesh filename="file://$(find rcj2025_description)/meshes/wheel_left_backward_link_1.stl" scale="0.001 0.001 0.001"/>
    </geometry>
    <material name="silver"/>
  </visual>
  <collision>
    <origin xyz="-0.074905 -0.032003 0.044995" rpy="0 0 0"/>
    <geometry>
      <mesh filename="file://$(find rcj2025_description)/meshes/wheel_left_backward_link_1.stl" scale="0.001 0.001 0.001"/>
    </geometry>
  </collision>
</link>


<joint name="wheel_left_forward_joint" type="continuous">
  <origin xyz="0.074905 0.032003 0.044995" rpy="0 0 0"/>
  <parent link="base_link"/>
  <child link="wheel_left_forward_link_1"/>
  <axis xyz="1.0 -0.0 -0.0"/>
</joint>

<joint name="wheel_right_forward_joint" type="continuous">
  <origin xyz="-0.074905 0.032003 0.044995" rpy="0 0 0"/>
  <parent link="base_link"/>
  <child link="wheel_right_forward_link_1"/>
  <axis xyz="1.0 0.0 0.0"/>
</joint>

<joint name="wheel_right_backward_joint" type="continuous">
  <origin xyz="-0.074905 0.032003 -0.044995" rpy="0 0 0"/>
  <parent link="base_link"/>
  <child link="wheel_right_backward_link_1"/>
  <axis xyz="-1.0 -0.0 0.0"/>
</joint>

<joint name="wheel_left_backward_joint" type="continuous">
  <origin xyz="0.074905 0.032003 -0.044995" rpy="0 0 0"/>
  <parent link="base_link"/>
  <child link="wheel_left_backward_link_1"/>
  <axis xyz="-1.0 0.0 -0.0"/>
</joint>

</robot>
